<robot name = "robot">
    <link name="Torso">
        <inertial>
            <origin xyz="-4 0 3" rpy="0 0 0"/>
            <mass value="1" />
            <inertia ixx="100" ixy="0" ixz="0" iyy="100" iyz="0" izz="100" />
        </inertial>
        <visual>
            <origin xyz="-4 0 3" rpy="0 0 0"/>
            <geometry>
                <box size="1.3175645076584712 1 1" />
            </geometry>
            <material name="Green">
            <color rgba="0 1 0 1"/>
            </material>
        </visual>
        <collision>
            <origin xyz="-4 0 3" rpy="0 0 0"/>
            <geometry>
                <box size="1.3175645076584712 1 1" />
            </geometry>
        </collision>
    </link>
    <joint name="Torso_lungs" type="revolute">
       <parent link="Torso"/>
       <child  link="lungs"/>
       <origin rpy="0 0 0" xyz="-3.3412177461707646 0 3" />
     <axis xyz="0 1 0"/>
       <limit effort="0.0" lower="-3.14159" upper="3.14159" velocity="0.0"/>
    </joint>
    <link name="lungs">
        <inertial>
            <origin xyz="0.44743427658731655 0 0" rpy="0 0 0"/>
            <mass value="1" />
            <inertia ixx="100" ixy="0" ixz="0" iyy="100" iyz="0" izz="100" />
        </inertial>
        <visual>
            <origin xyz="0.44743427658731655 0 0" rpy="0 0 0"/>
            <geometry>
                <box size="0.8948685531746331 0.34111743394323346 0.2095707914171272" />
            </geometry>
            <material name="Blue">
            <color rgba="0 0 1 1"/>
            </material>
        </visual>
        <collision>
            <origin xyz="0.44743427658731655 0 0" rpy="0 0 0"/>
            <geometry>
                <box size="0.8948685531746331 0.34111743394323346 0.2095707914171272" />
            </geometry>
        </collision>
    </link>
    <joint name="lungs_bladder" type="revolute">
       <parent link="lungs"/>
       <child  link="bladder"/>
       <origin rpy="0 0 0" xyz="0.8948685531746331 0 0" />
     <axis xyz="0 1 0"/>
       <limit effort="0.0" lower="-3.14159" upper="3.14159" velocity="0.0"/>
    </joint>
    <link name="bladder">
        <inertial>
            <origin xyz="0.14152927592790748 0 0" rpy="0 0 0"/>
            <mass value="1" />
            <inertia ixx="100" ixy="0" ixz="0" iyy="100" iyz="0" izz="100" />
        </inertial>
        <visual>
            <origin xyz="0.14152927592790748 0 0" rpy="0 0 0"/>
            <geometry>
                <box size="0.28305855185581497 0.7042561274183264 0.15372420304624268" />
            </geometry>
            <material name="Blue">
            <color rgba="0 0 1 1"/>
            </material>
        </visual>
        <collision>
            <origin xyz="0.14152927592790748 0 0" rpy="0 0 0"/>
            <geometry>
                <box size="0.28305855185581497 0.7042561274183264 0.15372420304624268" />
            </geometry>
        </collision>
    </link>
    <joint name="bladder_kidney" type="revolute">
       <parent link="bladder"/>
       <child  link="kidney"/>
       <origin rpy="0 0 0" xyz="0.28305855185581497 0 0" />
     <axis xyz="0 1 0"/>
       <limit effort="0.0" lower="-3.14159" upper="3.14159" velocity="0.0"/>
    </joint>
    <link name="kidney">
        <inertial>
            <origin xyz="0.027734592830218563 0 0" rpy="0 0 0"/>
            <mass value="1" />
            <inertia ixx="100" ixy="0" ixz="0" iyy="100" iyz="0" izz="100" />
        </inertial>
        <visual>
            <origin xyz="0.027734592830218563 0 0" rpy="0 0 0"/>
            <geometry>
                <box size="0.055469185660437126 0.855246027502417 0.27780710591550173" />
            </geometry>
            <material name="Blue">
            <color rgba="0 0 1 1"/>
            </material>
        </visual>
        <collision>
            <origin xyz="0.027734592830218563 0 0" rpy="0 0 0"/>
            <geometry>
                <box size="0.055469185660437126 0.855246027502417 0.27780710591550173" />
            </geometry>
        </collision>
    </link>
    <joint name="kidney_stomach" type="revolute">
       <parent link="kidney"/>
       <child  link="stomach"/>
       <origin rpy="0 0 0" xyz="0.055469185660437126 0 0" />
     <axis xyz="0 1 0"/>
       <limit effort="0.0" lower="-3.14159" upper="3.14159" velocity="0.0"/>
    </joint>
    <link name="stomach">
        <inertial>
            <origin xyz="0.3520438112702023 0 0" rpy="0 0 0"/>
            <mass value="1" />
            <inertia ixx="100" ixy="0" ixz="0" iyy="100" iyz="0" izz="100" />
        </inertial>
        <visual>
            <origin xyz="0.3520438112702023 0 0" rpy="0 0 0"/>
            <geometry>
                <box size="0.7040876225404046 0.163236120055133 0.4487204597128963" />
            </geometry>
            <material name="Green">
            <color rgba="0 1 0 1"/>
            </material>
        </visual>
        <collision>
            <origin xyz="0.3520438112702023 0 0" rpy="0 0 0"/>
            <geometry>
                <box size="0.7040876225404046 0.163236120055133 0.4487204597128963" />
            </geometry>
        </collision>
    </link>
    <joint name="stomach_intestine" type="revolute">
       <parent link="stomach"/>
       <child  link="intestine"/>
       <origin rpy="0 0 0" xyz="0.7040876225404046 0 0" />
     <axis xyz="0 1 0"/>
       <limit effort="0.0" lower="-3.14159" upper="3.14159" velocity="0.0"/>
    </joint>
    <link name="intestine">
        <inertial>
            <origin xyz="0.0272664841460023 0 0" rpy="0 0 0"/>
            <mass value="1" />
            <inertia ixx="100" ixy="0" ixz="0" iyy="100" iyz="0" izz="100" />
        </inertial>
        <visual>
            <origin xyz="0.0272664841460023 0 0" rpy="0 0 0"/>
            <geometry>
                <box size="0.0545329682920046 0.9718885179653312 0.9687772159828055" />
            </geometry>
            <material name="Blue">
            <color rgba="0 0 1 1"/>
            </material>
        </visual>
        <collision>
            <origin xyz="0.0272664841460023 0 0" rpy="0 0 0"/>
            <geometry>
                <box size="0.0545329682920046 0.9718885179653312 0.9687772159828055" />
            </geometry>
        </collision>
    </link>
    <joint name="intestine_heart" type="revolute">
       <parent link="intestine"/>
       <child  link="heart"/>
       <origin rpy="0 0 0" xyz="0.0545329682920046 0 0" />
     <axis xyz="0 1 0"/>
       <limit effort="0.0" lower="-3.14159" upper="3.14159" velocity="0.0"/>
    </joint>
    <link name="heart">
        <inertial>
            <origin xyz="0.4408836199778063 0 0" rpy="0 0 0"/>
            <mass value="1" />
            <inertia ixx="100" ixy="0" ixz="0" iyy="100" iyz="0" izz="100" />
        </inertial>
        <visual>
            <origin xyz="0.4408836199778063 0 0" rpy="0 0 0"/>
            <geometry>
                <box size="0.8817672399556126 0.6900020409402926 0.7921315783068796" />
            </geometry>
            <material name="Green">
            <color rgba="0 1 0 1"/>
            </material>
        </visual>
        <collision>
            <origin xyz="0.4408836199778063 0 0" rpy="0 0 0"/>
            <geometry>
                <box size="0.8817672399556126 0.6900020409402926 0.7921315783068796" />
            </geometry>
        </collision>
    </link>
    <joint name="heart_finger" type="revolute">
       <parent link="heart"/>
       <child  link="finger"/>
       <origin rpy="0 0 0" xyz="0.8817672399556126 0 0" />
     <axis xyz="0 1 0"/>
       <limit effort="0.0" lower="-3.14159" upper="3.14159" velocity="0.0"/>
    </joint>
    <link name="finger">
        <inertial>
            <origin xyz="0.36596639565714156 0 0" rpy="0 0 0"/>
            <mass value="1" />
            <inertia ixx="100" ixy="0" ixz="0" iyy="100" iyz="0" izz="100" />
        </inertial>
        <visual>
            <origin xyz="0.36596639565714156 0 0" rpy="0 0 0"/>
            <geometry>
                <box size="0.7319327913142831 0.8644973587842858 0.9985708215268283" />
            </geometry>
            <material name="Blue">
            <color rgba="0 0 1 1"/>
            </material>
        </visual>
        <collision>
            <origin xyz="0.36596639565714156 0 0" rpy="0 0 0"/>
            <geometry>
                <box size="0.7319327913142831 0.8644973587842858 0.9985708215268283" />
            </geometry>
        </collision>
    </link>
    <joint name="finger_leg" type="revolute">
       <parent link="finger"/>
       <child  link="leg"/>
       <origin rpy="0 0 0" xyz="0.7319327913142831 0 0" />
     <axis xyz="0 1 0"/>
       <limit effort="0.0" lower="-3.14159" upper="3.14159" velocity="0.0"/>
    </joint>
    <link name="leg">
        <inertial>
            <origin xyz="0.08340408293229518 0 0" rpy="0 0 0"/>
            <mass value="1" />
            <inertia ixx="100" ixy="0" ixz="0" iyy="100" iyz="0" izz="100" />
        </inertial>
        <visual>
            <origin xyz="0.08340408293229518 0 0" rpy="0 0 0"/>
            <geometry>
                <box size="0.16680816586459035 0.5191346406634993 0.39203835599980796" />
            </geometry>
            <material name="Blue">
            <color rgba="0 0 1 1"/>
            </material>
        </visual>
        <collision>
            <origin xyz="0.08340408293229518 0 0" rpy="0 0 0"/>
            <geometry>
                <box size="0.16680816586459035 0.5191346406634993 0.39203835599980796" />
            </geometry>
        </collision>
    </link>
</robot>